ERROR 2024-10-24 21:31:40,430 log Internal Server Error: /admin/auth/user/3/delete/
Traceback (most recent call last):
  File "C:\Users\Priyesh Pandey\AppData\Roaming\Python\Python310\site-packages\django\db\backends\utils.py", line 89, in _execute
    return self.cursor.execute(sql, params)
  File "C:\Users\Priyesh Pandey\AppData\Roaming\Python\Python310\site-packages\django\db\backends\mysql\base.py", line 75, in execute
    return self.cursor.execute(query, args)
  File "C:\Users\Priyesh Pandey\AppData\Roaming\Python\Python310\site-packages\MySQLdb\cursors.py", line 206, in execute
    res = self._query(query)
  File "C:\Users\Priyesh Pandey\AppData\Roaming\Python\Python310\site-packages\MySQLdb\cursors.py", line 319, in _query
    db.query(q)
  File "C:\Users\Priyesh Pandey\AppData\Roaming\Python\Python310\site-packages\MySQLdb\connections.py", line 254, in query
    _mysql.connection.query(self, query)
MySQLdb.ProgrammingError: (1146, "Table 'agratasinfotech.aipl_addtaskdetail' doesn't exist")

The above exception was the direct cause of the following exception:

Traceback (most recent call last):
  File "C:\Users\Priyesh Pandey\AppData\Roaming\Python\Python310\site-packages\django\core\handlers\exception.py", line 55, in inner
    response = get_response(request)
  File "C:\Users\Priyesh Pandey\AppData\Roaming\Python\Python310\site-packages\django\core\handlers\base.py", line 197, in _get_response
    response = wrapped_callback(request, *callback_args, **callback_kwargs)
  File "C:\Users\Priyesh Pandey\AppData\Roaming\Python\Python310\site-packages\django\contrib\admin\options.py", line 683, in wrapper
    return self.admin_site.admin_view(view)(*args, **kwargs)
  File "C:\Users\Priyesh Pandey\AppData\Roaming\Python\Python310\site-packages\django\utils\decorators.py", line 133, in _wrapped_view
    response = view_func(request, *args, **kwargs)
  File "C:\Users\Priyesh Pandey\AppData\Roaming\Python\Python310\site-packages\django\views\decorators\cache.py", line 62, in _wrapped_view_func
    response = view_func(request, *args, **kwargs)
  File "C:\Users\Priyesh Pandey\AppData\Roaming\Python\Python310\site-packages\django\contrib\admin\sites.py", line 242, in inner
    return view(request, *args, **kwargs)
  File "C:\Users\Priyesh Pandey\AppData\Roaming\Python\Python310\site-packages\django\utils\decorators.py", line 46, in _wrapper
    return bound_method(*args, **kwargs)
  File "C:\Users\Priyesh Pandey\AppData\Roaming\Python\Python310\site-packages\django\utils\decorators.py", line 133, in _wrapped_view
    response = view_func(request, *args, **kwargs)
  File "C:\Users\Priyesh Pandey\AppData\Roaming\Python\Python310\site-packages\django\contrib\admin\options.py", line 2104, in delete_view
    return self._delete_view(request, object_id, extra_context)
  File "C:\Users\Priyesh Pandey\AppData\Roaming\Python\Python310\site-packages\django\contrib\admin\options.py", line 2132, in _delete_view
    ) = self.get_deleted_objects([obj], request)
  File "C:\Users\Priyesh Pandey\AppData\Roaming\Python\Python310\site-packages\django\contrib\admin\options.py", line 2099, in get_deleted_objects
    return get_deleted_objects(objs, request, self.admin_site)
  File "C:\Users\Priyesh Pandey\AppData\Roaming\Python\Python310\site-packages\django\contrib\admin\utils.py", line 120, in get_deleted_objects
    collector.collect(objs)
  File "C:\Users\Priyesh Pandey\AppData\Roaming\Python\Python310\site-packages\django\contrib\admin\utils.py", line 186, in collect
    return super().collect(objs, source_attr=source_attr, **kwargs)
  File "C:\Users\Priyesh Pandey\AppData\Roaming\Python\Python310\site-packages\django\db\models\deletion.py", line 341, in collect
    if sub_objs:
  File "C:\Users\Priyesh Pandey\AppData\Roaming\Python\Python310\site-packages\django\db\models\query.py", line 324, in __bool__
    self._fetch_all()
  File "C:\Users\Priyesh Pandey\AppData\Roaming\Python\Python310\site-packages\django\db\models\query.py", line 1507, in _fetch_all
    self._result_cache = list(self._iterable_class(self))
  File "C:\Users\Priyesh Pandey\AppData\Roaming\Python\Python310\site-packages\django\db\models\query.py", line 57, in __iter__
    results = compiler.execute_sql(
  File "C:\Users\Priyesh Pandey\AppData\Roaming\Python\Python310\site-packages\django\db\models\sql\compiler.py", line 1361, in execute_sql
    cursor.execute(sql, params)
  File "C:\Users\Priyesh Pandey\AppData\Roaming\Python\Python310\site-packages\django\db\backends\utils.py", line 103, in execute
    return super().execute(sql, params)
  File "C:\Users\Priyesh Pandey\AppData\Roaming\Python\Python310\site-packages\django\db\backends\utils.py", line 67, in execute
    return self._execute_with_wrappers(
  File "C:\Users\Priyesh Pandey\AppData\Roaming\Python\Python310\site-packages\django\db\backends\utils.py", line 80, in _execute_with_wrappers
    return executor(sql, params, many, context)
  File "C:\Users\Priyesh Pandey\AppData\Roaming\Python\Python310\site-packages\django\db\backends\utils.py", line 84, in _execute
    with self.db.wrap_database_errors:
  File "C:\Users\Priyesh Pandey\AppData\Roaming\Python\Python310\site-packages\django\db\utils.py", line 91, in __exit__
    raise dj_exc_value.with_traceback(traceback) from exc_value
  File "C:\Users\Priyesh Pandey\AppData\Roaming\Python\Python310\site-packages\django\db\backends\utils.py", line 89, in _execute
    return self.cursor.execute(sql, params)
  File "C:\Users\Priyesh Pandey\AppData\Roaming\Python\Python310\site-packages\django\db\backends\mysql\base.py", line 75, in execute
    return self.cursor.execute(query, args)
  File "C:\Users\Priyesh Pandey\AppData\Roaming\Python\Python310\site-packages\MySQLdb\cursors.py", line 206, in execute
    res = self._query(query)
  File "C:\Users\Priyesh Pandey\AppData\Roaming\Python\Python310\site-packages\MySQLdb\cursors.py", line 319, in _query
    db.query(q)
  File "C:\Users\Priyesh Pandey\AppData\Roaming\Python\Python310\site-packages\MySQLdb\connections.py", line 254, in query
    _mysql.connection.query(self, query)
django.db.utils.ProgrammingError: (1146, "Table 'agratasinfotech.aipl_addtaskdetail' doesn't exist")
ERROR 2024-10-24 21:31:40,454 basehttp "GET /admin/auth/user/3/delete/ HTTP/1.1" 500 217984
